Traceback (most recent call last):
  File "/opt/hostedtoolcache/Python/3.11.10/x64/lib/python3.11/site-packages/jupyter_cache/executors/utils.py", line 58, in single_nb_execution
    executenb(
  File "/opt/hostedtoolcache/Python/3.11.10/x64/lib/python3.11/site-packages/nbclient/client.py", line 1269, in execute
    return NotebookClient(nb=nb, resources=resources, km=km, **kwargs).execute()
           ^^^^^^^^^^^^^^^^^^^^^^^^^^^^^^^^^^^^^^^^^^^^^^^^^^^^^^^^^^^^^^^^^^^^^
  File "/opt/hostedtoolcache/Python/3.11.10/x64/lib/python3.11/site-packages/nbclient/util.py", line 85, in wrapped
    return just_run(coro(*args, **kwargs))
           ^^^^^^^^^^^^^^^^^^^^^^^^^^^^^^^
  File "/opt/hostedtoolcache/Python/3.11.10/x64/lib/python3.11/site-packages/nbclient/util.py", line 60, in just_run
    return loop.run_until_complete(coro)
           ^^^^^^^^^^^^^^^^^^^^^^^^^^^^^
  File "/opt/hostedtoolcache/Python/3.11.10/x64/lib/python3.11/asyncio/base_events.py", line 654, in run_until_complete
    return future.result()
           ^^^^^^^^^^^^^^^
  File "/opt/hostedtoolcache/Python/3.11.10/x64/lib/python3.11/site-packages/nbclient/client.py", line 707, in async_execute
    await self.async_execute_cell(
  File "/opt/hostedtoolcache/Python/3.11.10/x64/lib/python3.11/site-packages/nbclient/client.py", line 1025, in async_execute_cell
    await self._check_raise_for_error(cell, cell_index, exec_reply)
  File "/opt/hostedtoolcache/Python/3.11.10/x64/lib/python3.11/site-packages/nbclient/client.py", line 919, in _check_raise_for_error
    raise CellExecutionError.from_cell_and_msg(cell, exec_reply_content)
nbclient.exceptions.CellExecutionError: An error occurred while executing the following cell:
------------------
validation_result = model.validate()
print(f"Model is valid? {validation_result.valid}")

# print reasons
for uri, diffset in validation_result.diffset.items():
    for diff in diffset:
        print(f" - {diff.reason()}")
------------------

[0;31m---------------------------------------------------------------------------[0m
[0;31mException[0m                                 Traceback (most recent call last)
Cell [0;32mIn[2], line 1[0m
[0;32m----> 1[0m validation_result [38;5;241m=[39m [43mmodel[49m[38;5;241;43m.[39;49m[43mvalidate[49m[43m([49m[43m)[49m
[1;32m      2[0m [38;5;28mprint[39m([38;5;124mf[39m[38;5;124m"[39m[38;5;124mModel is valid? [39m[38;5;132;01m{[39;00mvalidation_result[38;5;241m.[39mvalid[38;5;132;01m}[39;00m[38;5;124m"[39m)
[1;32m      4[0m [38;5;66;03m# print reasons[39;00m

File [0;32m~/work/BuildingMOTIF/BuildingMOTIF/buildingmotif/dataclasses/model.py:178[0m, in [0;36mModel.validate[0;34m(self, shape_collections, error_on_missing_imports)[0m
[1;32m    176[0m [38;5;66;03m# aggregate shape graphs[39;00m
[1;32m    177[0m [38;5;28;01mfor[39;00m sc [38;5;129;01min[39;00m shape_collections:
[0;32m--> 178[0m     shapeg [38;5;241m+[39m[38;5;241m=[39m [43msc[49m[38;5;241;43m.[39;49m[43mresolve_imports[49m[43m([49m
[1;32m    179[0m [43m        [49m[43merror_on_missing_imports[49m[38;5;241;43m=[39;49m[43merror_on_missing_imports[49m
[1;32m    180[0m [43m    [49m[43m)[49m[38;5;241m.[39mgraph
[1;32m    181[0m [38;5;66;03m# inline sh:node for interpretability[39;00m
[1;32m    182[0m shapeg [38;5;241m=[39m rewrite_shape_graph(shapeg)

File [0;32m~/work/BuildingMOTIF/BuildingMOTIF/buildingmotif/dataclasses/shape_collection.py:134[0m, in [0;36mShapeCollection.resolve_imports[0;34m(self, recursive_limit, error_on_missing_imports)[0m
[1;32m    117[0m [38;5;250m[39m[38;5;124;03m"""Resolves `owl:imports` to as many levels as requested.[39;00m
[1;32m    118[0m 
[1;32m    119[0m [38;5;124;03mBy default, all `owl:imports` are recursively resolved. This limit can[39;00m
[0;32m   (...)[0m
[1;32m    131[0m [38;5;124;03m:rtype: ShapeCollection[39;00m
[1;32m    132[0m [38;5;124;03m"""[39;00m
[1;32m    133[0m resolved_namespaces: Set[rdflib[38;5;241m.[39mURIRef] [38;5;241m=[39m [38;5;28mset[39m()
[0;32m--> 134[0m resolved [38;5;241m=[39m [43m_resolve_imports[49m[43m([49m
[1;32m    135[0m [43m    [49m[38;5;28;43mself[39;49m[38;5;241;43m.[39;49m[43mgraph[49m[43m,[49m
[1;32m    136[0m [43m    [49m[43mrecursive_limit[49m[43m,[49m
[1;32m    137[0m [43m    [49m[43mresolved_namespaces[49m[43m,[49m
[1;32m    138[0m [43m    [49m[43merror_on_missing_imports[49m[38;5;241;43m=[39;49m[43merror_on_missing_imports[49m[43m,[49m
[1;32m    139[0m [43m[49m[43m)[49m
[1;32m    140[0m new_sc [38;5;241m=[39m ShapeCollection[38;5;241m.[39mcreate()
[1;32m    141[0m new_sc[38;5;241m.[39madd_graph(resolved)

File [0;32m~/work/BuildingMOTIF/BuildingMOTIF/buildingmotif/dataclasses/shape_collection.py:473[0m, in [0;36m_resolve_imports[0;34m(graph, recursive_limit, seen, error_on_missing_imports)[0m
[1;32m    471[0m [38;5;28;01mif[39;00m sc_to_add [38;5;129;01mis[39;00m [38;5;28;01mNone[39;00m:
[1;32m    472[0m     [38;5;28;01mif[39;00m error_on_missing_imports:
[0;32m--> 473[0m         [38;5;28;01mraise[39;00m [38;5;167;01mException[39;00m([38;5;124m"[39m[38;5;124mCould not resolve import of [39m[38;5;132;01m%s[39;00m[38;5;124m"[39m, ontology)
[1;32m    474[0m     [38;5;28;01mcontinue[39;00m
[1;32m    476[0m dependency [38;5;241m=[39m _resolve_imports(
[1;32m    477[0m     sc_to_add[38;5;241m.[39mgraph,
[1;32m    478[0m     recursive_limit [38;5;241m-[39m [38;5;241m1[39m,
[1;32m    479[0m     seen,
[1;32m    480[0m     error_on_missing_imports[38;5;241m=[39merror_on_missing_imports,
[1;32m    481[0m )

[0;31mException[0m: ('Could not resolve import of %s', rdflib.term.URIRef('https://brickschema.org/schema/1.3/Brick'))
Exception: ('Could not resolve import of %s', rdflib.term.URIRef('https://brickschema.org/schema/1.3/Brick'))

