Traceback (most recent call last):
  File "/opt/hostedtoolcache/Python/3.11.3/x64/lib/python3.11/site-packages/jupyter_cache/executors/utils.py", line 58, in single_nb_execution
    executenb(
  File "/opt/hostedtoolcache/Python/3.11.3/x64/lib/python3.11/site-packages/nbclient/client.py", line 1269, in execute
    return NotebookClient(nb=nb, resources=resources, km=km, **kwargs).execute()
           ^^^^^^^^^^^^^^^^^^^^^^^^^^^^^^^^^^^^^^^^^^^^^^^^^^^^^^^^^^^^^^^^^^^^^
  File "/opt/hostedtoolcache/Python/3.11.3/x64/lib/python3.11/site-packages/nbclient/util.py", line 85, in wrapped
    return just_run(coro(*args, **kwargs))
           ^^^^^^^^^^^^^^^^^^^^^^^^^^^^^^^
  File "/opt/hostedtoolcache/Python/3.11.3/x64/lib/python3.11/site-packages/nbclient/util.py", line 60, in just_run
    return loop.run_until_complete(coro)
           ^^^^^^^^^^^^^^^^^^^^^^^^^^^^^
  File "/opt/hostedtoolcache/Python/3.11.3/x64/lib/python3.11/asyncio/base_events.py", line 653, in run_until_complete
    return future.result()
           ^^^^^^^^^^^^^^^
  File "/opt/hostedtoolcache/Python/3.11.3/x64/lib/python3.11/site-packages/nbclient/client.py", line 707, in async_execute
    await self.async_execute_cell(
  File "/opt/hostedtoolcache/Python/3.11.3/x64/lib/python3.11/site-packages/nbclient/client.py", line 1025, in async_execute_cell
    await self._check_raise_for_error(cell, cell_index, exec_reply)
  File "/opt/hostedtoolcache/Python/3.11.3/x64/lib/python3.11/site-packages/nbclient/client.py", line 919, in _check_raise_for_error
    raise CellExecutionError.from_cell_and_msg(cell, exec_reply_content)
nbclient.exceptions.CellExecutionError: An error occurred while executing the following cell:
------------------
my_graph = rdflib.Graph()
# parse files:
# my_graph.parse("my_external_file.ttl")
# or parse raw strings:
my_graph.parse(data='''
@prefix bldg: <urn:ex/> .
@prefix brick: <https://brickschema.org/schema/Brick#> .
bldg:A1 a brick:Air_Handler_Unit .
''')
model.add_graph(my_graph)
------------------

[0;31m---------------------------------------------------------------------------[0m
[0;31mNameError[0m                                 Traceback (most recent call last)
Cell [0;32mIn[6], line 1[0m
[0;32m----> 1[0m my_graph [38;5;241m=[39m [43mrdflib[49m[38;5;241m.[39mGraph()
[1;32m      2[0m [38;5;66;03m# parse files:[39;00m
[1;32m      3[0m [38;5;66;03m# my_graph.parse("my_external_file.ttl")[39;00m
[1;32m      4[0m [38;5;66;03m# or parse raw strings:[39;00m
[1;32m      5[0m my_graph[38;5;241m.[39mparse(data[38;5;241m=[39m[38;5;124m'''[39m
[1;32m      6[0m [38;5;124m@prefix bldg: <urn:ex/> .[39m
[1;32m      7[0m [38;5;124m@prefix brick: <https://brickschema.org/schema/Brick#> .[39m
[1;32m      8[0m [38;5;124mbldg:A1 a brick:Air_Handler_Unit .[39m
[1;32m      9[0m [38;5;124m'''[39m)

[0;31mNameError[0m: name 'rdflib' is not defined
NameError: name 'rdflib' is not defined

